Workbook

Sheet Informações Iniciais

Sheet Quadro Geral
B2: NÃO PREENCHER
B3: Desempenho por Especialidade (Ciclo Regular)
B4: Disciplina | C4: Tarefas Feitas | D4: % Tarefas Feitas | E4: Questões Feitas | F4: % Acertos
B5: Pediatria | C5: =Pediatria!E101 -> 7 | D5: ='Quadro Geral'!$C5/97 -> 0.072164948 | E5: =Pediatria!F101 -> 192 | F5: =Pediatria!H101 -> 0.796875
B6: Cirurgia | C6: =Cirurgia!E89 -> 5 | D6: =Cirurgia!E89/85 -> 0.058823529 | E6: =Cirurgia!F89 -> 190 | F6: =Cirurgia!H89 -> 0.78421053
B7: Ginecologia | C7: =Ginecologia!E67 -> 5 | D7: =Ginecologia!E67/63 -> 0.079365079 | E7: =Ginecologia!F67 -> 188 | F7: =Ginecologia!H67 -> 0.7712766
B8: Preventiva | C8: =Preventiva!E91 -> 8 | D8: =Preventiva!E91/87 -> 0.091954023 | E8: =Preventiva!F91 -> 309 | F8: =Preventiva!H91 -> 0.77993528
B9: Obstetrícia | C9: ='Obstetrícia'!E65 -> 5 | D9: ='Obstetrícia'!E65/61 -> 0.081967213 | E9: ='Obstetrícia'!G65 -> 115 | F9: ='Obstetrícia'!H65 -> 0.85185185
B10: Infecto | C10: =Infectologia!E49 -> 6 | D10: =Infectologia!E49/45 -> 0.13333333 | E10: =Infectologia!F49 -> 158 | F10: =Infectologia!H49 -> 0.78481013
B11: Gastro | C11: =Gastro!E35 -> 2 | D11: =Gastro!E35/31 -> 0.064516129 | E11: =Gastro!F35 -> 78 | F11: =Gastro!H35 -> 0.78205128
B12: Cardiologia | C12: =Cardiologia!E36 -> 2 | D12: ='Quadro Geral'!$C12/32 -> 0.0625 | E12: =Cardiologia!F36 -> 26 | F12: =Cardiologia!H36 -> 0.57692308
B13: Nefrologia | C13: =Nefrologia!E27 -> 1 | D13: =Nefrologia!E27/23 -> 0.043478261 | E13: =Nefrologia!F27 -> 40 | F13: =Nefrologia!H27 -> 0.8
B14: Endocrino | C14: =Endocrino!E36 -> 2 | D14: ='Quadro Geral'!$C14/32 -> 0.0625 | E14: =Endocrino!F36 -> 76 | F14: =Endocrino!H36 -> 0.72368421
B15: Hepato | C15: =Hepato!E22 -> 0 | D15: ='Quadro Geral'!$C15/18 -> 0 | E15: =Hepato!F22 -> 0 | F15: =Hepato!H22 -> #DIV/0!
B16: Neuro | C16: =Neurologia!E24 -> 6 | D16: ='Quadro Geral'!$C16/20 -> 0.3 | E16: =Neurologia!F24 -> 528 | F16: =Neurologia!H24 -> 0.78409091
B17: Pneumo | C17: =Pneumo!E24 -> 2 | D17: ='Quadro Geral'!$C17/20 -> 0.1 | E17: =Pneumo!F24 -> 44 | F17: =Pneumo!H24 -> 0.75
B18: Otorrino | C18: =Otorrino!E15 -> 0 | D18: ='Quadro Geral'!$C18/11 -> 0 | E18: =Otorrino!F15 -> 0 | F18: =Otorrino!H15 -> #DIV/0!
B19: Psiquiatria | C19: =Psiquiatria!E21 -> 0 | D19: ='Quadro Geral'!$C19/17 -> 0 | E19: =Psiquiatria!F21 -> 0 | F19: =Psiquiatria!H21 -> #DIV/0!
B20: Reumato | C20: =Reumato!E21 -> 0 | D20: ='Quadro Geral'!$C20/17 -> 0 | E20: =Reumato!F21 -> 0 | F20: =Reumato!H21 -> #DIV/0!
B21: Hemato | C21: =Hematologia!E22 -> 1 | D21: ='Quadro Geral'!$C21/18 -> 0.055555556 | E21: =Hematologia!F22 -> 20 | F21: =Hematologia!H22 -> 0.9
B22: Dermato | C22: =Dermato!E13 -> 0 | D22: ='Quadro Geral'!$C22/9 -> 0 | E22: =Dermato!F13 -> 0 | F22: =Dermato!H13 -> #DIV/0!
B23: Ortopedia | C23: =Ortopedia!E18 -> 0 | D23: ='Quadro Geral'!$C23/14 -> 0 | E23: =Ortopedia!F18 -> 0 | F23: =Ortopedia!H18 -> #DIV/0!
B24: Oftalmo | C24: =Oftalmo!E11 -> 0 | D24: ='Quadro Geral'!$C24/7 -> 0 | E24: =Oftalmo!F11 -> 0 | F24: =Oftalmo!H11 -> #DIV/0!
B25: Total | C25: =SUM(C5:C24) -> 52 | D25: =SUM(D5:D24)/20 -> 0.060307904 | E25: =SUM(E5:E24) -> 1964 | F25: =#REF!/'Quadro Geral'!$E25 -> #REF!
B27: Mês de referência | C27: Valor acumulado pago | D27: Questões até o último dia | E27: Custo / Questão | F27: C/Q
B28: 45870 | C28: 840 | D28: 549 | E28: =C28/D28 -> 1.5300546 | F28: C/Q > 1,50
B29: 45901 | C29: 1050 | D29: 884 | E29: =C29/D29 -> 1.1877828 | F29: 0,75 < C/Q < 1,25 | H29: C/Q > 1,50
B30: 45931 | C30: 1260 | D30: 1032 | E30: =C30/D30 -> 1.2209302 | F30: 0,75 < C/Q < 1,25 | H30: 1,25 < C/Q < 1,50
B31: 45962 | C31: 1470 | D31: 1032 | E31: =C31/D31 -> 1.4244186 | F31: 1,25 < C/Q < 1,5 | H31: 0,75 < C/Q < 1,25
B32: 45992 | C32: 1680 | D32: 1032 | E32: =C32/D32 -> 1.627907 | F32: C/Q > 1,50 | H32: 0,50 < C/Q < 0,75
B33: 46023 | C33: 1890 | D33: 1032 | E33: =C33/D33 -> 1.8313953 | F33: C/Q > 1,50 | H33: C/Q < R$0,50
B34: 46054 | C34: 2100 | D34: 1116 | E34: =C34/D34 -> 1.8817204 | F34: C/Q > 1,50
B35: 46082 | C35: 2310 | D35: 1749 | E35: =C35/D35 -> 1.3207547 | F35: 1,25 < C/Q < 1,5
B36: 46113 | C36: 2520
B37: 46143 | C37: 2730

Sheet Pediatria
A1: Sim
C2: Sim | E2: PREENCHER | F2: PREENCHER | G2: PREENCHER | H2: NAO PREENCHER!
B3: Tarefa | C3: Assunto | D3: Tipo de Tarefa | E3: Realizada? | F3: Questões Feitas | G3: Acertos | H3: % Acertos
B4: 1 | C4: Imunizações | D4: Teoria I | H4: =Pediatria!$G4/Pediatria!$F4 -> #DIV/0!
B5: 2 | C5: Imunizações | D5: Teoria II | H5: =Pediatria!$G5/Pediatria!$F5 -> #DIV/0!
B6: 3 | C6: Imunizações | D6: Teoria III | H6: =Pediatria!$G6/Pediatria!$F6 -> #DIV/0!
B7: 4 | C7: Imunizações | D7: Revisão | H7: =Pediatria!$G7/Pediatria!$F7 -> #DIV/0!
B8: 5 | C8: Doenças Exantemáticas | D8: Teoria I | H8: =Pediatria!$G8/Pediatria!$F8 -> #DIV/0!
B9: 6 | C9: Doenças Exantemáticas | D9: Teoria II | H9: =Pediatria!$G9/Pediatria!$F9 -> #DIV/0!
B10: 7 | C10: Doenças Exantemáticas | D10: Revisão | H10: =Pediatria!$G10/Pediatria!$F10 -> #DIV/0!
B11: 8 | C11: Icterícia e Sepse Neonatal | D11: Teoria I | H11: =Pediatria!$G11/Pediatria!$F11 -> #DIV/0!
B12: 9 | C12: Icterícia e Sepse Neonatal | D12: Teoria II | H12: =Pediatria!$G12/Pediatria!$F12 -> #DIV/0!
B13: 10 | C13: Icterícia e Sepse Neonatal | D13: Revisão | H13: =Pediatria!$G13/Pediatria!$F13 -> #DIV/0!
B14: 11 | C14: Emergências Pediátricas | D14: Teoria I | E14: Sim | F14: 28 | G14: 24 | H14: =Pediatria!$G14/Pediatria!$F14 -> 0.85714286
B15: 12 | C15: Emergências Pediátricas | D15: Teoria II | H15: =Pediatria!$G15/Pediatria!$F15 -> #DIV/0!
B16: 13 | C16: Emergências Pediátricas | D16: Teoria III | H16: =Pediatria!$G16/Pediatria!$F16 -> #DIV/0!
B17: 14 | C17: Emergências Pediátricas | D17: Revisão | H17: =Pediatria!$G17/Pediatria!$F17 -> #DIV/0!
B18: 15 | C18: Imunizações Doenças Exantemáticas Icterícia e Sepse Neonatal Emergências Pediátricas | D18: Revisão por Questões | H18: =Pediatria!$G18/Pediatria!$F18 -> #DIV/0!
B19: 16 | C19: Cardiopatias Congênitas | D19: Teoria I | E19: Sim | F19: 20 | G19: 16 | H19: =Pediatria!$G19/Pediatria!$F19 -> 0.8
B20: 17 | C20: Cardiopatias Congênitas | D20: Teoria II | E20: Sim | F20: 20 | G20: 13 | H20: =Pediatria!$G20/Pediatria!$F20 -> 0.65
B21: 18 | C21: Cardiopatias Congênitas | D21: Revisão | E21: Sim | F21: 40 | G21: 34 | H21: =Pediatria!$G21/Pediatria!$F21 -> 0.85
B22: 19 | C22: Cuidados Neonatais | D22: Teoria I | E22: Sim | F22: 24 | G22: 17 | H22: =Pediatria!$G22/Pediatria!$F22 -> 0.70833333
B23: 20 | C23: Cuidados Neonatais | D23: Teoria II | E23: Sim | F23: 20 | G23: 15 | H23: =Pediatria!$G23/Pediatria!$F23 -> 0.75
B24: 21 | C24: Cuidados Neonatais | D24: Revisão | E24: Sim | F24: 40 | G24: 34 | H24: =Pediatria!$G24/Pediatria!$F24 -> 0.85
B25: 22 | C25: Asma | D25: Teoria I | H25: =Pediatria!$G25/Pediatria!$F25 -> #DIV/0!
B26: 23 | C26: Asma | D26: Teoria II | H26: =Pediatria!$G26/Pediatria!$F26 -> #DIV/0!
B27: 24 | C27: Asma | D27: Teoria III | H27: =Pediatria!$G27/Pediatria!$F27 -> #DIV/0!
B28: 25 | C28: Asma | D28: Revisão | H28: =Pediatria!$G28/Pediatria!$F28 -> #DIV/0!
B29: 26 | C29: Aleitamento Materno | D29: Teoria I | H29: =Pediatria!$G29/Pediatria!$F29 -> #DIV/0!
B30: 27 | C30: Aleitamento Materno | D30: Teoria II | H30: =Pediatria!$G30/Pediatria!$F30 -> #DIV/0!
B31: 28 | C31: Aleitamento Materno | D31: Revisão | H31: =Pediatria!$G31/Pediatria!$F31 -> #DIV/0!
B32: 29 | C32: Cardiopatias Congênitas Cuidados Neonatais Asma Aleitamento Materno | D32: Revisão por Questões | H32: =Pediatria!$G32/Pediatria!$F32 -> #DIV/0!
B33: 30 | C33: Diarreia | D33: Teoria I | H33: =Pediatria!$G33/Pediatria!$F33 -> #DIV/0!
B34: 31 | C34: Diarreia | D34: Teoria II | H34: =Pediatria!$G34/Pediatria!$F34 -> #DIV/0!
B35: 32 | C35: Diarreia | D35: Revisão | H35: =Pediatria!$G35/Pediatria!$F35 -> #DIV/0!
B36: 33 | C36: Pneumonias na Infância | D36: Teoria I | H36: =Pediatria!$G36/Pediatria!$F36 -> #DIV/0!
... B49: 46 | C49: Crescimento | D49: Revisão | H49: =Pediatria!$G49/Pediatria!$F49 -> #DIV/0!
B50: 47 | C50: Doença Celíaca em Pediatria Febre Reumática | D50: Teoria
B51: 48 | C51: Tópicos em Pediatria | D51: Teoria | H51: =Pediatria!$G51/Pediatria!$F51 -> #DIV/0!
B52: 49 | C52: Tópicos em Pediatria | D52: Revisão | H52: =Pediatria!$G52/Pediatria!$F52 -> #DIV/0!
...

Sheet Preventiva
A1: Sim
C2: Sim | E2: PREENCHER | F2: PREENCHER | G2: PREENCHER | H2: NAO PREENCHER!
B3: Tarefa | C3: Assunto | D3: Tipo de Tarefa | E3: Realizada? | F3: Questões Feitas | G3: Acertos | H3: % Acertos
B4: 1 | C4: Vigilância em Saúde | D4: Teoria | E4: Sim | F4: 92 | G4: 69 | H4: =Preventiva!$G4/Preventiva!F4 -> 0.75
B5: 2 | C5: Vigilância em Saúde | D5: Revisão | H5: =Preventiva!$G5/Preventiva!$F5 -> #DIV/0!
B6: 3 | C6: Sistemas de Informação em Saúde | D6: Teoria I | H6: =Preventiva!$G6/Preventiva!$F6 -> #DIV/0!
B7: 4 | C7: Sistemas de Informação em Saúde | D7: Teoria II | H7: =Preventiva!$G7/Preventiva!$F7 -> #DIV/0!
B8: 5 | C8: Sistemas de Informação em Saúde | D8: Teoria III | H8: =Preventiva!$G8/Preventiva!$F8 -> #DIV/0!
B9: 6 | C9: Sistemas de Informação em Saúde | D9: Revisão | H9: =Preventiva!$G9/Preventiva!$F9 -> #DIV/0!
B10: 7 | C10: Vigilância em Saúde Sistemas de Informação em Saúde | D10: Revisão por Questões | H10: =Preventiva!$G10/Preventiva!$F10 -> #DIV/0!
B11: 27 | C11: Medidas de Saúde Coletiva Pt. I Medidas de Saúde Coletiva Pt. II Medidas de Saúde Coletiva Pt. III | D11: Revisão por Questões | H11: =Preventiva!$G11/Preventiva!$F11 -> #DIV/0!
B12: 8 | C12: Medidas de Saúde Coletiva Pt. I | D12: Teoria I | E12: Sim | F12: 28 | G12: 21 | H12: =Preventiva!$G12/Preventiva!$F12 -> 0.75
B13: 9 | C13: Medidas de Saúde Coletiva Pt. I | D13: Teoria II | E13: Sim | F13: 43 | G13: 33 | H13: =Preventiva!$G13/Preventiva!$F13 -> 0.76744186
B14: 10 | C14: Medidas de Saúde Coletiva Pt. I | D14: Revisão I | E14: Sim | F14: 47 | G14: 38 | H14: =Preventiva!$G14/Preventiva!$F14 -> 0.80851064
B15: 11 | C15: Medidas de Saúde Coletiva Pt. I | D15: Teoria III | H15: =Preventiva!$G15/Preventiva!$F15 -> #DIV/0!
B16: 12 | C16: Medidas de Saúde Coletiva Pt. I | D16: Teoria IV | H16: =Preventiva!$G16/Preventiva!$F16 -> #DIV/0!
B17: 13 | C17: Medidas de Saúde Coletiva Pt. I | D17: Revisão II | H17: =Preventiva!$G17/Preventiva!$F17 -> #DIV/0!
B18: 14 | C18: Medidas de Saúde Coletiva Pt. II | D18: Teoria I | E18: Sim | F18: 19 | G18: 11 | H18: =Preventiva!$G18/Preventiva!$F18 -> 0.57894737
B19: 15 | C19: Medidas de Saúde Coletiva Pt. II | D19: Teoria II | H19: =Preventiva!$G19/Preventiva!$F19 -> #DIV/0!
B20: 16 | C20: Medidas de Saúde Coletiva Pt. II | D20: Revisão I | H20: =Preventiva!$G20/Preventiva!$F20 -> #DIV/0!
B21: 17 | C21: Medidas de Saúde Coletiva Pt. II | D21: Teoria III | H21: =Preventiva!$G21/Preventiva!$F21 -> #DIV/0!
B22: 18 | C22: Medidas de Saúde Coletiva Pt. II | D22: Teoria IV | H22: =Preventiva!$G22/Preventiva!$F22 -> #DIV/0!
B23: 19 | C23: Medidas de Saúde Coletiva Pt. II | D23: Revisão II | H23: =Preventiva!$G23/Preventiva!$F23 -> #DIV/0!
B24: 20 | C24: Medidas de Saúde Coletiva Pt. III | D24: Teoria I | H24: =Preventiva!$G24/Preventiva!$F24 -> #DIV/0!
B25: 21 | C25: Medidas de Saúde Coletiva Pt. III | D25: Teoria II | H25: =Preventiva!$G25/Preventiva!$F25 -> #DIV/0!
B26: 22 | C26: Medidas de Saúde Coletiva Pt. III | D26: Revisão I | H26: =Preventiva!$G26/Preventiva!$F26 -> #DIV/0!
B27: 23 | C27: Medidas de Saúde Coletiva Pt. III | D27: Teoria III | H27: =Preventiva!$G27/Preventiva!$F27 -> #DIV/0!
B28: 24 | C28: Medidas de Saúde Coletiva Pt. III | D28: Teoria IV | H28: =Preventiva!$G28/Preventiva!$F28 -> #DIV/0!
B29: 25 | C29: Medidas de Saúde Coletiva Pt. III | D29: Revisão II | H29: =Preventiva!$G29/Preventiva!$F29 -> #DIV/0!
B30: 26 | C30: Processo Saúde-Doença | D30: Teoria I | E30: Sim | F30: 20 | G30: 17 | H30: =Preventiva!$G30/Preventiva!$F30 -> 0.85
B31: 28 | C31: Processo Saúde-Doença | D31: Teoria II | E31: Sim | F31: 19 | G31: 14 | H31: =Preventiva!$G31/Preventiva!$F31 -> 0.73684211
B32: 29 | C32: Processo Saúde-Doença | D32: Revisão | E32: Sim | F32: 41 | G32: 38 | H32: =Preventiva!$G32/Preventiva!$F32 -> 0.92682927
B33: 30 | C33: Medicina de Família e Comunidade | D33: Teoria I | H33: =Preventiva!$G33/Preventiva!$F33 -> #DIV/0!
B34: 31 | C34: Medicina de Família e Comunidade | D34: Teoria II | H34: =Preventiva!$G34/Preventiva!$F34 -> #DIV/0!
B35: 32 | C35: Medicina de Família e Comunidade | D35: Revisão | H35: =Preventiva!$G35/Preventiva!$F35 -> #DIV/0!
B36: 33 | C36: Saúde do Idoso | D36: Teoria | H36: =Preventiva!$G36/Preventiva!$F36 -> #DIV/0!
B37: 34 | C37: Saúde do Idoso | D37: Revisão | H37: =Preventiva!$G37/Preventiva!$F37 -> #DIV/0!
B38: 35 | C38: Processo Saúde-Doença Medicina de Família e Comunidade Saúde do Idoso | D38: Revisão por Questões | H38: =Preventiva!$G38/Preventiva!$F38 -> #DIV/0!
B39: 36 | C39: Princípios e Diretrizes do SUS | D39: Teoria I | H39: =Preventiva!$G39/Preventiva!$F39 -> #DIV/0!
B40: 37 | C40: Princípios e Diretrizes do SUS | D40: Teoria II | H40: =Preventiva!$G40/Preventiva!$F40 -> #DIV/0!
...

Sheet Cirurgia
A1: Sim
C2: Sim | E2: PREENCHER | F2: PREENCHER | G2: PREENCHER | H2: NAO PREENCHER!
B3: Tarefa | C3: Assunto | D3: Tipo de Tarefa | E3: Realizada? | F3: Questões Feitas | G3: Acertos | H3: % Acertos
B4: 1 | C4: Cirurgia Infantil I | D4: Teoria I | H4: =Cirurgia!$G4/Cirurgia!$F4 -> #DIV/0!
B5: 2 | C5: Cirurgia Infantil I | D5: Teoria II | H5: =Cirurgia!$G5/Cirurgia!$F5 -> #DIV/0!
B6: 3 | C6: Cirurgia Infantil I | D6: Revisão | H6: =Cirurgia!$G6/Cirurgia!$F6 -> #DIV/0!
B7: 4 | C7: Cirurgia Infantil II | D7: Teoria I | H7: =Cirurgia!$G7/Cirurgia!$F7 -> #DIV/0!
B8: 5 | C8: Cirurgia Infantil II | D8: Teoria II | H8: =Cirurgia!$G8/Cirurgia!$F8 -> #DIV/0!
B9: 6 | C9: Cirurgia Infantil II | D9: Revisão | H9: =Cirurgia!$G9/Cirurgia!$F9 -> #DIV/0!
B10: 7 | C10: Cirurgia Infantil III | D10: Teoria I | H10: =Cirurgia!$G10/Cirurgia!$F10 -> #DIV/0!
B11: 8 | C11: Cirurgia Infantil III | D11: Teoria II | H11: =Cirurgia!$G11/Cirurgia!$F11 -> #DIV/0!
B12: 9 | C12: Cirurgia Infantil III | D12: Revisão | H12: =Cirurgia!$G12/Cirurgia!$F12 -> #DIV/0!
B13: 10 | C13: Cirurgia Infantil Pt. I Cirurgia Infantil Pt. II Cirurgia Infantil Pt. III | D13: Revisão por Questões | H13: =Cirurgia!$G13/Cirurgia!$F13 -> #DIV/0!
B14: 11 | C14: Trauma - Avaliação Inicial, Vias Aéreas e Trauma Torácico | D14: Teoria I | E14: Sim | F14: 27 | G14: 21 | H14: =Cirurgia!$G14/Cirurgia!$F14 -> 0.77777778
B15: 12 | C15: Trauma - Avaliação Inicial, Vias Aéreas e Trauma Torácico | D15: Teoria II | E15: Sim | F15: 30 | G15: 21 | H15: =Cirurgia!$G15/Cirurgia!$F15 -> 0.7
B16: 13 | C16: Trauma - Avaliação Inicial, Vias Aéreas e Trauma Torácico | D16: Revisão | F16: 42 | G16: 31 | H16: =Cirurgia!$G16/Cirurgia!$F16 -> 0.73809524
B17: 14 | C17: Trauma - Choque | D17: Teoria I | E17: Sim | F17: 39 | G17: 33 | H17: =Cirurgia!$G17/Cirurgia!$F17 -> 0.84615385
B18: 15 | C18: Trauma - Choque | D18: Teoria II | E18: Sim | F18: 17 | G18: 13 | H18: =Cirurgia!$G18/Cirurgia!$F18 -> 0.76470588
B19: 16 | C19: Trauma - Choque | D19: Revisão | E19: Sim | F19: 35 | G19: 30 | H19: =Cirurgia!$G19/Cirurgia!$F19 -> 0.85714286
B20: 17 | C20: Trauma Abdominal e Pélvico | D20: Teoria I | H20: =Cirurgia!$G20/Cirurgia!$F20 -> #DIV/0!
B21: 18 | C21: Trauma Abdominal e Pélvico | D21: Teoria II | H21: =Cirurgia!$G21/Cirurgia!$F21 -> #DIV/0!
B22: 19 | C22: Trauma Abdominal e Pélvico | D22: Teoria III | H22: =Cirurgia!$G22/Cirurgia!$F22 -> #DIV/0!
B23: 20 | C23: Trauma Abdominal e Pélvico | D23: Revisão I | H23: =Cirurgia!$G23/Cirurgia!$F23 -> #DIV/0!
B24: 21 | C24: Trauma Abdominal e Pélvico | D24: Teoria IV | H24: =Cirurgia!$G24/Cirurgia!$F24 -> #DIV/0!
B25: 22 | C25: Trauma Abdominal e Pélvico | D25: Teoria V | H25: =Cirurgia!$G25/Cirurgia!$F25 -> #DIV/0!
B26: 23 | C26: Trauma Abdominal e Pélvico | D26: Revisão | H26: =Cirurgia!$G26/Cirurgia!$F26 -> #DIV/0!
B27: 24 | C27: Trauma - Avaliação Inicial, Vias Aéreas e Trauma Torácico Trauma - Choque Trauma Abdominal e Pélvico | D27: Revisão por Questões | H27: =Cirurgia!$G27/Cirurgia!$F27 -> #DIV/0!
B28: 25 | C28: Abdome Agudo Inflamatório - Apendicite Aguda | D28: Teoria I | H28: =Cirurgia!$G28/Cirurgia!$F28 -> #DIV/0!
B29: 26 | C29: Abdome Agudo Inflamatório - Apendicite Aguda | D29: Teoria II | H29: =Cirurgia!$G29/Cirurgia!$F29 -> #DIV/0!
B30: 27 | C30: Abdome Agudo Inflamatório - Apendicite Aguda | D30: Revisão | H30: =Cirurgia!$G30/Cirurgia!$F30 -> #DIV/0!
B31: 28 | C31: Abdome Agudo Inflamatório - Colecistite e Colangite Aguda | D31: Teoria I | H31: =Cirurgia!$G31/Cirurgia!$F31 -> #DIV/0!
... B88: 85 | C88: Queimaduras e Trauma Elétrico Abdome Agudo Perfurativo Proctologia Nutrição em cirurgia Temas Gerais em Cirurgia | D88: Revisão por Questões | H88: =Cirurgia!$G88/Cirurgia!$F88 -> #DIV/0!
B89: Total | E89: =COUNTA(E4:E88) -> 5 | F89: =SUM(F4:F88) -> 190 | G89: =SUM(G4:G88) -> 149 | H89: =Cirurgia!$G89/Cirurgia!$F89 -> 0.78421053

Sheet Infectologia
A1: Sim
C2: Sim | E2: PREENCHER | F2: PREENCHER | G2: PREENCHER | H2: NAO PREENCHER!
B3: Tarefa | C3: Assunto | D3: Tipo de Tarefa | E3: Realizada? | F3: Questões Feitas | G3: Acertos | H3: % Acertos
B4: 1 | C4: Arboviroses | D4: Teoria I | H4: =Infectologia!$G4/Infectologia!$F4 -> #DIV/0!
B5: 2 | C5: Arboviroses | D5: Teoria II | H5: =Infectologia!$G5/Infectologia!$F5 -> #DIV/0!
B6: 3 | C6: Arboviroses | D6: Teoria III | H6: =Infectologia!$G6/Infectologia!$F6 -> #DIV/0!
B7: 4 | C7: Arboviroses | D7: Revisão | H7: =Infectologia!$G7/Infectologia!$F7 -> #DIV/0!
B8: 5 | C8: HIV | D8: Teoria I | E8: Sim | F8: 28 | G8: 17 | H8: =Infectologia!$G8/Infectologia!$F8 -> 0.60714286
B9: 6 | C9: HIV | D9: Teoria II | E9: Sim | F9: 19 | G9: 17 | H9: =Infectologia!$G9/Infectologia!$F9 -> 0.89473684
B10: 7 | C10: HIV | D10: Teoria III | H10: =Infectologia!$G10/Infectologia!$F10 -> #DIV/0!
B11: 8 | C11: HIV | D11: Revisão | E11: Sim | F11: 39 | G11: 31 | H11: =Infectologia!$G11/Infectologia!$F11 -> 0.79487179
B12: 9 | C12: Tuberculose | D12: Teoria I | E12: Sim | F12: 18 | G12: 14 | H12: =Infectologia!$G12/Infectologia!$F12 -> 0.77777778
B13: 10 | C13: Tuberculose | D13: Teoria II | E13: Sim | F13: 19 | G13: 18 | H13: =Infectologia!$G13/Infectologia!$F13 -> 0.94736842
B14: 11 | C14: Tuberculose | D14: Revisão | E14: Sim | F14: 35 | G14: 27 | H14: =Infectologia!$G14/Infectologia!$F14 -> 0.77142857
B15: 12 | C15: Meningites e Meningoencefalites | D15: Teoria I | H15: =Infectologia!$G15/Infectologia!$F15 -> #DIV/0!
B16: 13 | C16: Meningites e Meningoencefalites | D16: Teoria II | H16: =Infectologia!$G16/Infectologia!$F16 -> #DIV/0!
B17: 14 | C17: Meningites e Meningoencefalites | D17: Teoria III | H17: =Infectologia!$G17/Infectologia!$F17 -> #DIV/0!
B18: 15 | C18: Meningites e Meningoencefalites | D18: Revisão | H18: =Infectologia!$G18/Infectologia!$F18 -> #DIV/0!
B19: 16 | C19: Arboviroses HIV Tuberculose Meningites e Meningoencefalites | D19: Revisão por Questões | H19: =Infectologia!$G19/Infectologia!$F19 -> #DIV/0!
B20: 17 | C20: Micoses Invasivas | D20: Teoria | H20: =Infectologia!$G20/Infectologia!$F20 -> #DIV/0!
B21: 18 | C21: Sepse | D21: Teoria I | H21: =Infectologia!$G21/Infectologia!$F21 -> #DIV/0!
B22: 19 | C22: Sepse | D22: Teoria II | H22: =Infectologia!$G22/Infectologia!$F22 -> #DIV/0!
B23: 20 | C23: Sepse | D23: Revisão | H23: =Infectologia!$G23/Infectologia!$F23 -> #DIV/0!
B24: 21 | C24: Neutropenia Febril e Febre de Origem Indeterminada Piodermites | D24: Teoria | H24: =Infectologia!$G24/Infectologia!$F24 -> #DIV/0!
B25: 22 | C25: Parasitoses | D25: Teoria I | H25: =Infectologia!$G25/Infectologia!$F25 -> #DIV/0!
B26: 23 | C26: Parasitoses | D26: Teoria II | H26: =Infectologia!$G26/Infectologia!$F26 -> #DIV/0!
... B48: 45 | C48: COVID Endocardite Bacteriana - Endocardite Infecciosa Antibióticos Animais Peçonhentos | D48: Revisão por Questões | H48: =Infectologia!$G48/Infectologia!$F48 -> #DIV/0!
B49: Total | E49: =COUNTA(E4:E48) -> 6 | F49: =SUM(F4:F48) -> 158 | G49: =SUM(G4:G48) -> 124 | H49: =Infectologia!$G49/Infectologia!$F49 -> 0.78481013

Sheet Obstetrícia
A1: Sim
C2: Sim | E2: PREENCHER | F2: PREENCHER | G2: PREENCHER | H2: NAO PREENCHER!
B3: Tarefa | C3: Assunto | D3: Tipo de Tarefa | E3: Realizada? | F3: Questões Feitas | G3: Acertos | H3: % Acertos
B4: 1 | C4: Pré-Natal | D4: Teoria I | H4: ='Obstetrícia'!$G4/'Obstetrícia'!$F4 -> #DIV/0!
B5: 2 | C5: Pré-Natal | D5: Teoria II | H5: ='Obstetrícia'!$G5/'Obstetrícia'!$F5 -> #DIV/0!
B6: 3 | C6: Pré-Natal | D6: Teoria III | H6: ='Obstetrícia'!$G6/'Obstetrícia'!$F6 -> #DIV/0!
B7: 4 | C7: Pré-Natal | D7: Revisão | H7: ='Obstetrícia'!$G7/'Obstetrícia'!$F7 -> #DIV/0!
B8: 5 | C8: Distúrbios Hipertensivos da Gestação | D8: Teoria I | H8: ='Obstetrícia'!$G8/'Obstetrícia'!$F8 -> #DIV/0!
B9: 6 | C9: Distúrbios Hipertensivos da Gestação | D9: Teoria II | H9: ='Obstetrícia'!$G9/'Obstetrícia'!$F9 -> #DIV/0!
B10: 7 | C10: Distúrbios Hipertensivos da Gestação | D10: Teoria III | H10: ='Obstetrícia'!$G10/'Obstetrícia'!$F10 -> #DIV/0!
B11: 8 | C11: Distúrbios Hipertensivos da Gestação | D11: Revisão | H11: ='Obstetrícia'!$G11/'Obstetrícia'!$F11 -> #DIV/0!
B12: 9 | C12: Sífilis na Gestação e Sífilis Congênita | D12: Teoria I | E12: Sim | F12: 28 | G12: 25 | H12: ='Obstetrícia'!$G12/'Obstetrícia'!$F12 -> 0.89285714
B13: 10 | C13: Sífilis na Gestação e Sífilis Congênita | D13: Teoria II | H13: ='Obstetrícia'!$G13/'Obstetrícia'!$F13 -> #DIV/0!
B14: 11 | C14: Sífilis na Gestação e Sífilis Congênita | D14: Revisão | H14: ='Obstetrícia'!$G14/'Obstetrícia'!$F14 -> #DIV/0!
B15: 12 | C15: Sangramento da Primeira Metade | D15: Teoria I | E15: Sim | F15: 17 | G15: 15 | H15: ='Obstetrícia'!$G15/'Obstetrícia'!$F15 -> 0.88235294
B16: 13 | C16: Sangramento da Primeira Metade | D16: Teoria II | E16: Sim | F16: 20 | G16: 15 | H16: ='Obstetrícia'!$G16/'Obstetrícia'!$F16 -> 0.75
B17: 14 | C17: Sangramento da Primeira Metade | D17: Teoria III | E17: Sim | F17: 22 | G17: 21 | H17: ='Obstetrícia'!$G17/'Obstetrícia'!$F17 -> 0.95454545
B18: 15 | C18: Sangramento da Primeira Metade | D18: Revisão | E18: Sim | F18: 48 | G18: 39 | H18: ='Obstetrícia'!$G18/'Obstetrícia'!$F18 -> 0.8125
B19: 16 | C19: Pré-Natal Distúbios Hipertensivos da Gestação Sífilis na Gestação e Sífilis Congênita Sangramento da Primeira Metade | D19: Revisão por Questões | H19: ='Obstetrícia'!$G19/'Obstetrícia'!$F19 -> #DIV/0!
B20: 17 | C20: Assistência ao Parto | D20: Teoria I | H20: ='Obstetrícia'!$G20/'Obstetrícia'!$F20 -> #DIV/0!
B21: 18 | C21: Assistência ao Parto | D21: Teoria II | H21: ='Obstetrícia'!$G21/'Obstetrícia'!$F21 -> #DIV/0!
B22: 19 | C22: Assistência ao Parto | D22: Teoria III | H22: ='Obstetrícia'!$G22/'Obstetrícia'!$F22 -> #DIV/0!
B23: 20 | C23: Assistência ao Parto | D23: Revisão | H23: ='Obstetrícia'!$G23/'Obstetrícia'!$F23 -> #DIV/0!
B24: 21 | C24: Vitalidade Fetal | D24: Teoria I | H24: ='Obstetrícia'!$G24/'Obstetrícia'!$F24 -> #DIV/0!
B25: 22 | C25: Vitalidade Fetal | D25: Teoria II | H25: ='Obstetrícia'!$G25/'Obstetrícia'!$F25 -> #DIV/0!
B26: 23 | C26: Vitalidade Fetal | D26: Teoria III | H26: ='Obstetrícia'!$G26/'Obstetrícia'!$F26 -> #DIV/0!
B27: 24 | C27: Vitalidade Fetal | D27: Revisão | H27: ='Obstetrícia'!$G27/'Obstetrícia'!$F27 -> #DIV/0!
B28: 25 | C28: Diabetes na Gestação | D28: Teoria | H28: ='Obstetrícia'!$G28/'Obstetrícia'!$F28 -> #DIV/0!
B29: 26 | C29: Diabetes na Gestação | D29: Revisão | H29: ='Obstetrícia'!$G29/'Obstetrícia'!$F29 -> #DIV/0!
B30: 27 | C30: Mecanismo de Parto e Fases Clínicas do Parto | D30: Teoria | H30: ='Obstetrícia'!$G30/'Obstetrícia'!$F30 -> #DIV/0!
... B64: 61 | C64: Prematuridade e Trabalho de Parto Prematuro Rotura Prematura de Membranas Restrição de Crescimento Fetal e Óbito Fetal Modificações Fisiológicas da Gestação | D64: Revisão por Questões | H64: ='Obstetrícia'!$G64/'Obstetrícia'!$F64 -> #DIV/0!
B65: Total | E65: =COUNTA(E4:E64) -> 5 | F65: =SUM(F4:F64) -> 135 | G65: =SUM(G4:G64) -> 115 | H65: ='Obstetrícia'!$G65/'Obstetrícia'!$F65 -> 0.85185185

Sheet Ginecologia
A1: Sim
C2: Sim | E2: PREENCHER | F2: PREENCHER | G2: PREENCHER | H2: NAO PREENCHER!
B3: Tarefa | C3: Assunto | D3: Tipo de Tarefa | E3: Realizada? | F3: Questões Feitas | G3: Acertos | H3: % Acertos
B4: 1 | C4: Planejamento Familiar | D4: Teoria I | H4: =Ginecologia!$G4/Ginecologia!$F4 -> #DIV/0!
B5: 2 | C5: Planejamento Familiar | D5: Teoria II | H5: =Ginecologia!$G5/Ginecologia!$F5 -> #DIV/0!
B6: 3 | C6: Planejamento Familiar | D6: Revisão | H6: =Ginecologia!$G6/Ginecologia!$F6 -> #DIV/0!
B7: 4 | C7: Úlceras Genitais | D7: Teoria | H7: =Ginecologia!$G7/Ginecologia!$F7 -> #DIV/0!
B8: 5 | C8: Úlceras Genitais | D8: Revisão | H8: =Ginecologia!$G8/Ginecologia!$F8 -> #DIV/0!
B9: 6 | C9: Rastreamento do Câncer de Colo Uterino | D9: Teoria I | E9: Sim | F9: 34 | G9: 29 | H9: =Ginecologia!$G9/Ginecologia!$F9 -> 0.85294118
B10: 7 | C10: Rastreamento do Câncer de Colo Uterino | D10: Teoria II | H10: =Ginecologia!$G10/Ginecologia!$F10 -> #DIV/0!
B11: 8 | C11: Rastreamento do Câncer de Colo Uterino | D11: Revisão | H11: =Ginecologia!$G11/Ginecologia!$F11 -> #DIV/0!
B12: 9 | C12: Climatério e Terapia Hormonal | D12: Teoria | E12: Sim | F12: 38 | G12: 26 | H12: =Ginecologia!$G12/Ginecologia!$F12 -> 0.68421053
B13: 10 | C13: Climatério e Terapia Hormonal | D13: Revisão | E13: Sim | F13: 46 | G13: 41 | H13: =Ginecologia!$G13/Ginecologia!$F13 -> 0.89130435
B14: 12 | C14: Planejamento Familiar Úlceras Genitais Rastreamento do Câncer de Colo Uterino Climatério e Terapia Hormonal | D14: Revisão por Questões | H14: =Ginecologia!$G14/Ginecologia!$F14 -> #DIV/0!
B15: 11 | C15: Doenças Benignas da Mama | D15: Teoria I | E15: Sim | F15: 26 | G15: 17 | H15: =Ginecologia!$G15/Ginecologia!$F15 -> 0.65384615
B16: 13 | C16: Doenças Benignas da Mama | D16: Teoria II | H16: =Ginecologia!$G16/Ginecologia!$F16 -> #DIV/0!
B17: 14 | C17: Doenças Benignas da Mama | D17: Revisão | E17: Sim | F17: 44 | G17: 32 | H17: =Ginecologia!$G17/Ginecologia!$F17 -> 0.72727273
B18: 15 | C18: Vulvovaginites | D18: Teoria I | H18: =Ginecologia!$G18/Ginecologia!$F18 -> #DIV/0!
B19: 16 | C19: Vulvovaginites | D19: Teoria II | H19: =Ginecologia!$G19/Ginecologia!$F19 -> #DIV/0!
B20: 17 | C20: Vulvovaginites | D20: Revisão | H20: =Ginecologia!$G20/Ginecologia!$F20 -> #DIV/0!
B21: 18 | C21: Endometriose | D21: Teoria I | H21: =Ginecologia!$G21/Ginecologia!$F21 -> #DIV/0!
B22: 19 | C22: Endometriose | D22: Teoria II | H22: =Ginecologia!$G22/Ginecologia!$F22 -> #DIV/0!
B23: 20 | C23: Endometriose | D23: Revisão | H23: =Ginecologia!$G23/Ginecologia!$F23 -> #DIV/0!
B24: 21 | C24: Câncer de Mama | D24: Teoria I | H24: =Ginecologia!$G24/Ginecologia!$F24 -> #DIV/0!
B25: 22 | C25: Câncer de Mama | D25: Teoria II | H25: =Ginecologia!$G25/Ginecologia!$F25 -> #DIV/0!
B26: 23 | C26: Câncer de Mama | D26: Teoria III | H26: =Ginecologia!$G26/Ginecologia!$F26 -> #DIV/0!
B27: 24 | C27: Câncer de Mama | D27: Revisão | H27: =Ginecologia!$G27/Ginecologia!$F27 -> #DIV/0!
B28: 25 | C28: Doenças Benignas da Mama Vulvovaginites Endometriose Câncer de Mama | D28: Revisão por Questões | H28: =Ginecologia!$G28/Ginecologia!$F28 -> #DIV/0!
B29: 26 | C29: Sangramento Uterino Anormal | D29: Teoria I | H29: =Ginecologia!$G29/Ginecologia!$F29 -> #DIV/0!
... B59: 56 | C59: Rastreamento do Câncer de Mama | D59: Teoria II | H59: =Ginecologia!$G59/Ginecologia!$F59 -> #DIV/0!
B60: 57 | C60: Rastreamento do Câncer de Mama | H60: =Ginecologia!$G60/Ginecologia!$F60 -> #DIV/0!
B61: 58 | C61: Síndrome dos Ovários Policísticos | D61: Teoria I | H61: =Ginecologia!$G61/Ginecologia!$F61 -> #DIV/0!
B62: 59 | C62: Síndrome dos Ovários Policísticos | D62: Teoria II | H62: =Ginecologia!$G62/Ginecologia!$F62 -> #DIV/0!
B63: 60 | C63: Síndrome dos Ovários Policísticos | D63: Revisão | H63: =Ginecologia!$G63/Ginecologia!$F63 -> #DIV/0!
B64: 61 | C64: Assistência à Vítima de Violência Sexual | D64: Teoria | H64: =Ginecologia!$G64/Ginecologia!$F64 -> #DIV/0!
B65: 62 | C65: Assistência à Vítima de Violência Sexual | D65: Revisão | H65: =Ginecologia!$G65/Ginecologia!$F65 -> #DIV/0!
B66: 63 | C66: Miomatose Rastreamento do Câncer de Mama Síndrome dos Ovários Policísticos Assistência à Vítima de Violência Sexual | D66: Revisão por Questões | H66: =Ginecologia!$G66/Ginecologia!$F66 -> #DIV/0!
B67: Total | E67: =COUNTA(E4:E66) -> 5 | F67: =SUM(F4:F66) -> 188 | G67: =SUM(G4:G66) -> 145 | H67: =Ginecologia!$G67/Ginecologia!$F67 -> 0.7712766

Sheet Gastro
A1: Sim
C2: Sim | E2: PREENCHER | F2: PREENCHER | G2: PREENCHER | H2: NAO PREENCHER!
B3: Tarefa | C3: Assunto | D3: Tipo de Tarefa | E3: Realizada? | F3: Questões Feitas | G3: Acertos | H3: % Acertos
B4: 1 | C4: Pólipos e Neoplasias Intestinais | D4: Teoria I | H4: =Gastro!$G4/Gastro!$F4 -> #DIV/0!
B5: 2 | C5: Pólipos e Neoplasias Intestinais | D5: Teoria II | H5: =Gastro!$G5/Gastro!$F5 -> #DIV/0!
B6: 3 | C6: Pólipos e Neoplasias Intestinais | D6: Revisão I | H6: =Gastro!$G6/Gastro!$F6 -> #DIV/0!
B7: 4 | C7: Pólipos e Neoplasias Intestinais | D7: Teoria III | H7: =Gastro!$G7/Gastro!$F7 -> #DIV/0!
B8: 5 | C8: Pólipos e Neoplasias Intestinais | D8: Teoria IV | H8: =Gastro!$G8/Gastro!$F8 -> #DIV/0!
B9: 6 | C9: Pólipos e Neoplasias Intestinais | D9: Revisão II | H9: =Gastro!$G9/Gastro!$F9 -> #DIV/0!
B10: 7 | C10: Pancreatite Aguda e Crônica | D10: Teoria I | H10: =Gastro!$G10/Gastro!$F10 -> #DIV/0!
B11: 8 | C11: Pancreatite Aguda e Crônica | D11: Teoria II | H11: =Gastro!$G11/Gastro!$F11 -> #DIV/0!
B12: 9 | C12: Pancreatite Aguda e Crônica | D12: Teoria III | H12: =Gastro!$G12/Gastro!$F12 -> #DIV/0!
B13: 10 | C13: Pancreatite Aguda e Crônica | D13: Revisão | H13: =Gastro!$G13/Gastro!$F13 -> #DIV/0!
B14: 11 | C14: Doença do Refluxo Gastroesofágico, Esofagites e Corpo Estranho | D14: Teoria I | E14: Sim | F14: 31 | G14: 24 | H14: =Gastro!$G14/Gastro!$F14 -> 0.77419355
B15: 12 | C15: Doença do Refluxo Gastroesofágico, Esofagites e Corpo Estranho | D15: Teoria II | H15: =Gastro!$G15/Gastro!$F15 -> #DIV/0!
B16: 13 | C16: Doença do Refluxo Gastroesofágico, Esofagites e Corpo Estranho | D16: Revisão | E16: Sim | F16: 47 | G16: 37 | H16: =Gastro!$G16/Gastro!$F16 -> 0.78723404
B17: 14 | C17: Pólipos e Neoplasias Intestinais Pancreatite Aguda e Crônica (Pancreatites) Doença do Refluxo Gastroesofágico, Esofagites e Corpo Estranho | D17: Revisão por Questões | H17: =Gastro!$G17/Gastro!$F17 -> #DIV/0!
B18: 15 | C18: Doença Inflamatória Intestinal | D18: Teoria I | H18: =Gastro!$G18/Gastro!$F18 -> #DIV/0!
B19: 16 | C19: Doença Inflamatória Intestinal | D19: Teoria II | H19: =Gastro!$G19/Gastro!$F19 -> #DIV/0!
B20: 17 | C20: Doença Inflamatória Intestinal | D20: Revisão | H20: =Gastro!$G20/Gastro!$F20 -> #DIV/0!
B21: 18 | C21: Síndromes Disabsortivas Tumores Neuroendócrinos | D21: Teoria | H21: =Gastro!$G21/Gastro!$F21 -> #DIV/0!
B22: 19 | C22: Neoplasias de Estômago e Esôfago | D22: Teoria I | H22: =Gastro!$G22/Gastro!$F22 -> #DIV/0!
B23: 20 | C23: Neoplasias de Estômago e Esôfago | D23: Teoria II | H23: =Gastro!$G23/Gastro!$F23 -> #DIV/0!
B24: 21 | C24: Neoplasias de Estômago e Esôfago | D24: Teoria III | H24: =Gastro!$G24/Gastro!$F24 -> #DIV/0!
B25: 22 | C25: Neoplasias de Estômago e Esôfago | D25: Revisão | H25: =Gastro!$G25/Gastro!$F25 -> #DIV/0!
B26: 23 | C26: Anatomia do Intestino e Síndrome do Intestino Irritável | D26: Teoria | H26: =Gastro!$G26/Gastro!$F26 -> #DIV/0!
B27: 24 | C27: Anatomia do Intestino e Síndrome do Intestino Irritável | D27: Revisão | H27: =Gastro!$G27/Gastro!$F27 -> #DIV/0!
B28: 25 | C28: Doença Inflamatória Intestinal Neoplasias de Estômago e Esôfago Anatomia do Intestino e Síndrome do Intestino Irritável | D28: Revisão por Questões | H28: =Gastro!$G28/Gastro!$F28 -> #DIV/0!
... B34: 31 | C34: Disfagia, Alterações Estruturais e Dist. Motilidade Hemorragia Digestiva Alta Varicosa | D34: Revisão por Questões | H34: =Gastro!$G34/Gastro!$F34 -> #DIV/0!
B35: Total | E35: =COUNTA(E4:E34) -> 2 | F35: =SUM(F4:F34) -> 78 | G35: =SUM(G4:G34) -> 61 | H35: =Gastro!$G35/Gastro!$F35 -> 0.78205128

Sheet Endocrino
A1: Sim
C2: Sim | E2: PREENCHER | F2: PREENCHER | G2: PREENCHER | H2: NAO PREENCHER!
B3: Tarefa | C3: Assunto | D3: Tipo de Tarefa | E3: Realizada? | F3: Questões Feitas | G3: Acertos | H3: % Acertos
B4: 1 | C4: Tireotoxicose | D4: Teoria I | H4: =Endocrino!$G4/Endocrino!$F4 -> #DIV/0!
B5: 2 | C5: Tireotoxicose | D5: Teoria II | H5: =Endocrino!$G5/Endocrino!$F5 -> #DIV/0!
B6: 3 | C6: Tireotoxicose | D6: Revisão | H6: =Endocrino!$G6/Endocrino!$F6 -> #DIV/0!
B7: 4 | C7: Introdução ao Diabetes Mellitus Insulinoterapia e Cirurgia Metabólica | D7: Teoria | E7: Sim | F7: 29 | G7: 21 | H7: =Endocrino!$G7/Endocrino!$F7 -> 0.72413793
B8: 5 | C8: Diabetes Mellitus - Complicações Agudas | D8: Teoria I | H8: =Endocrino!$G8/Endocrino!$F8 -> #DIV/0!
B9: 6 | C9: Diabetes Mellitus - Complicações Agudas | D9: Teoria II | H9: =Endocrino!$G9/Endocrino!$F9 -> #DIV/0!
B10: 7 | C10: Diabetes Mellitus - Complicações Agudas | D10: Revisão | H10: =Endocrino!$G10/Endocrino!$F10 -> #DIV/0!
B11: 8 | C11: Adrenal - Hipocortisolismo | D11: Teoria | H11: =Endocrino!$G11/Endocrino!$F11 -> #DIV/0!
B12: 9 | C12: Metabolismo Ósseo e Mineral - Princípios e Fisiologia Hipercalcemia | D12: Teoria | H12: =Endocrino!$G12/Endocrino!$F12 -> #DIV/0!
B13: 10 | C13: Diabetes Mellitus Tipo 2 | D13: Teoria I | E13: Sim | F13: 47 | G13: 34 | H13: =Endocrino!$G13/Endocrino!$F13 -> 0.72340426
B14: 11 | C14: Diabetes Mellitus Tipo 2 | D14: Teoria II | H14: =Endocrino!$G14/Endocrino!$F14 -> #DIV/0!
B15: 12 | C15: Perioperatório - Controle Glicêmico e Manejo dos Glicocorticóides | D15: Teoria | H15: =Endocrino!$G15/Endocrino!$F15 -> #DIV/0!
B16: 13 | C16: Diabetes Mellitus Tipo 2 Perioperatório - Controle Glicêmico e Manejo dos Glicocorticóides | D16: Revisão | H16: =Endocrino!$G16/Endocrino!$F16 -> #DIV/0!
B17: 14 | C17: Tireotoxicose Diabetes Mellitus - Complicações Agudas Diabetes Mellitus Tipo 2 | D17: Revisão por Questões | H17: =Endocrino!$G17/Endocrino!$F17 -> #DIV/0!
B18: 15 | C18: Metabolismo Ósseo e Mineral - Vitamina D e Osteomalácia | D18: Teoria | H18: =Endocrino!$G18/Endocrino!$F18 -> #DIV/0!
B19: 16 | C19: Tireoide - Fisiologia, Semiologia e Avaliação Diagnóstica | D19: Teoria | H19: =Endocrino!$G19/Endocrino!$F19 -> #DIV/0!
B20: 17 | C20: Hipotireoidismo | D20: Teoria | H20: =Endocrino!$G20/Endocrino!$F20 -> #DIV/0!
B21: 18 | C21: Hipotireoidismo | D21: Revisão | H21: =Endocrino!$G21/Endocrino!$F21 -> #DIV/0!
B22: 19 | C22: Diabetes Mellitus - Complicações Crônicas | D22: Teoria I | H22: =Endocrino!$G22/Endocrino!$F22 -> #DIV/0!
B23: 20 | C23: Diabetes Mellitus - Complicações Crônicas | D23: Teoria II | H23: =Endocrino!$G23/Endocrino!$F23 -> #DIV/0!
B24: 21 | C24: Diabetes Mellitus - Complicações Crônicas | D24: Revisão | H24: =Endocrino!$G24/Endocrino!$F24 -> #DIV/0!
B25: 22 | C25: Perioperatório - Controle Glicêmico e Manejo dos Glicocorticóides Hipotireoidismo Diabetes Mellitus - Complicações Crônicas | D25: Revisão por Questões | H25: =Endocrino!$G25/Endocrino!$F25 -> #DIV/0!
... B35: 32 | C35: Obesidade e Síndrome Metabólica Cirurgia Bariátrica e Metabólica (Tratamento Cir. Obesidade) Osteoporose e Doença óssea de Paget | D35: Revisão por Questões | H35: =Endocrino!$G35/Endocrino!$F35 -> #DIV/0!
B36: Total | E36: =COUNTA(E4:E35) -> 2 | F36: =SUM(F4:F35) -> 76 | G36: =SUM(G4:G35) -> 55 | H36: =Endocrino!$G36/Endocrino!$F36 -> 0.72368421

Sheet Cardiologia
A1: Sim
C2: Sim | E2: PREENCHER | F2: PREENCHER | G2: PREENCHER | H2: NAO PREENCHER!
B3: Tarefa | C3: Assunto | D3: Tipo de Tarefa | E3: Realizada? | F3: Questões Feitas | G3: Acertos | H3: % Acertos
B4: 1 | C4: Hipertensão Arterial Sistêmica Pt. 1 | D4: Teoria I | H4: =Cardiologia!$G4/Cardiologia!$F4 -> #DIV/0!
B5: 2 | C5: Hipertensão Arterial Sistêmica Pt. 1 | D5: Teoria II | H5: =Cardiologia!$G5/Cardiologia!$F5 -> #DIV/0!
B6: 3 | C6: Hipertensão Arterial Sistêmica Pt. 2 | D6: Teoria I | H6: =Cardiologia!$G6/Cardiologia!$F6 -> #DIV/0!
B7: 4 | C7: Hipertensão Arterial Sistêmica Pt. 1 Hipertensão Arterial Sistêmica Pt. 2 (Teoria I) | D7: Revisão I | H7: =Cardiologia!$G7/Cardiologia!$F7 -> #DIV/0!
B8: 5 | C8: Hipertensão Arterial Sistêmica Pt. 2 | D8: Teoria II | H8: =Cardiologia!$G8/Cardiologia!$F8 -> #DIV/0!
B9: 6 | C9: Hipertensão Arterial Sistêmica Pt. 3 | D9: Teoria I | H9: =Cardiologia!$G9/Cardiologia!$F9 -> #DIV/0!
B10: 7 | C10: Hipertensão Arterial Sistêmica Pt. 3 | D10: Teoria II | H10: =Cardiologia!$G10/Cardiologia!$F10 -> #DIV/0!
B11: 8 | C11: Hipertensão Arterial Sistêmica Pt. 1 Hipertensão Arterial Sistêmica Pt. 2 Hipertensão Arterial Sistêmica Pt. 3 | D11: Revisão | H11: =Cardiologia!$G11/Cardiologia!$F11 -> #DIV/0!
B12: 9 | C12: Avaliação Perioperatória | D12: Teoria | H12: =Cardiologia!$G12/Cardiologia!$F12 -> #DIV/0!
B13: 10 | C13: Avaliação Perioperatória | D13: Revisão | H13: =Cardiologia!$G13/Cardiologia!$F13 -> #DIV/0!
B14: 11 | C14: Hipertensão Arterial Sistêmica Pt. 1 Hipertensão Arterial Sistêmica Pt. 2 Hipertensão Arterial Sistêmica Pt. 3 Avaliação Perioperatória | D14: Revisão por Questões | H14: =Cardiologia!$G14/Cardiologia!$F14 -> #DIV/0!
B15: 12 | C15: Insuficiência Cardíaca Pt.1 | D15: Teoria I | E15: Sim | F15: 13 | G15: 7 | H15: =Cardiologia!$G15/Cardiologia!$F15 -> 0.53846154
B16: 13 | C16: Insuficiência Cardíaca Pt.1 | D16: Teoria II | H16: =Cardiologia!$G16/Cardiologia!$F16 -> #DIV/0!
B17: 14 | C17: Insuficiência Cardíaca Pt.1 | D17: Revisão | H17: =Cardiologia!$G17/Cardiologia!$F17 -> #DIV/0!
B18: 15 | C18: Parada Cardiorrespiratória Dislipidemia e Estratificação de Risco Cardiovascular | D18: Teoria | H18: =Cardiologia!$G18/Cardiologia!$F18 -> #DIV/0!
B19: 16 | C19: Fibrilação e Flutter Atrial | D19: Teoria | H19: =Cardiologia!$G19/Cardiologia!$F19 -> #DIV/0!
B20: 17 | C20: Insuficiência Cardíaca Pt.2 | D20: Teoria I | E20: Sim | F20: 13 | G20: 8 | H20: =Cardiologia!$G20/Cardiologia!$F20 -> 0.61538462
B21: 18 | C21: Insuficiência Cardíaca Pt.2 | D21: Teoria II | H21: =Cardiologia!$G21/Cardiologia!$F21 -> #DIV/0!
B22: 19 | C22: Insuficiência Cardíaca Aguda | D22: Teoria | H22: =Cardiologia!$G22/Cardiologia!$F22 -> #DIV/0!
B23: 20 | C23: Insuficiência Cardíaca Pt.1 Insuficiência Cardíaca Pt.2 Insuficiência Cardíaca Aguda | D23: Revisão | H23: =Cardiologia!$G23/Cardiologia!$F23 -> #DIV/0!
B24: 21 | C24: Eletrocardiograma | D24: Teoria | H24: =Cardiologia!$G24/Cardiologia!$F24 -> #DIV/0!
B25: 22 | C25: Taquiarritmias Bradiarritmias | D25: Teoria | H25: =Cardiologia!$G25/Cardiologia!$F25 -> #DIV/0!
B26: 23 | C26: Valvopatias | D26: Teoria I | H26: =Cardiologia!$G26/Cardiologia!$F26 -> #DIV/0!
B27: 24 | C27: Valvopatias | D27: Teoria II | H27: =Cardiologia!$G27/Cardiologia!$F27 -> #DIV/0!
B28: 25 | C28: Valvopatias | D28: Teoria III | H28: =Cardiologia!$G28/Cardiologia!$F28 -> #DIV/0!
B29: 26 | C29: Valvopatias | D29: Revisão | H29: =Cardiologia!$G29/Cardiologia!$F29 -> #DIV/0!
B30: 27 | C30: SCASSST Síncope | D30: Teoria | H30: =Cardiologia!$G30/Cardiologia!$F30 -> #DIV/0!
B31: 28 | C31: Síndromes Aórticas Agudas (Resumo) Cardiomiopatias (Resumo) Pericardiopatias | D31: Teoria | H31: =Cardiologia!$G31/Cardiologia!$F31 -> #DIV/0!
B32: 29 | C32: IAMCSSST | D32: Teoria I | H32: =Cardiologia!$G32/Cardiologia!$F32 -> #DIV/0!
... B35: 32 | C35: Insuficiência Cardíaca Pt.1 Insuficiência Cardíaca Pt.2 Insuficiência Cardíaca Aguda Valvopatias IAMCSSST | D35: Revisão por Questões | H35: =Cardiologia!$G35/Cardiologia!$F35 -> #DIV/0!
B36: Total | E36: =COUNTA(E4:E35) -> 2 | F36: =SUM(F4:F35) -> 26 | G36: =SUM(G4:G35) -> 15 | H36: =Cardiologia!$G36/Cardiologia!$F36 -> 0.57692308

Sheet Psiquiatria
A1: Sim
C2: Sim | E2: PREENCHER | F2: PREENCHER | G2: PREENCHER | H2: NAO PREENCHER!
B3: Tarefa | C3: Assunto | D3: Tipo de Tarefa | E3: Realizada? | F3: Questões Feitas | G3: Acertos | H3: % Acertos
B4: 1 | C4: Intoxicações Exógenas | D4: Teoria I | H4: =Psiquiatria!$G4/Psiquiatria!$F4 -> #DIV/0!
B5: 2 | C5: Intoxicações Exógenas | D5: Teoria II | H5: =Psiquiatria!$G5/Psiquiatria!$F5 -> #DIV/0!
B6: 3 | C6: Intoxicações Exógenas | D6: Revisão | H6: =Psiquiatria!$G6/Psiquiatria!$F6 -> #DIV/0!
B7: 4 | C7: Dependência Química | D7: Teoria I | H7: =Psiquiatria!$G7/Psiquiatria!$F7 -> #DIV/0!
B8: 5 | C8: Dependência Química | D8: Teoria II | H8: =Psiquiatria!$G8/Psiquiatria!$F8 -> #DIV/0!
B9: 6 | C9: Dependência Química | D9: Revisão | H9: =Psiquiatria!$G9/Psiquiatria!$F9 -> #DIV/0!
B10: 7 | C10: Transtornos Psicóticos | D10: Teoria | H10: =Psiquiatria!$G10/Psiquiatria!$F10 -> #DIV/0!
B11: 8 | C11: Transtorno de Ansiedade | D11: Teoria | H11: =Psiquiatria!$G11/Psiquiatria!$F11 -> #DIV/0!
B12: 9 | C12: Transtornos de Humor | D12: Teoria | H12: =Psiquiatria!$G12/Psiquiatria!$F12 -> #DIV/0!
B13: 10 | C13: Transtornos de Humor | D13: Revisão | H13: =Psiquiatria!$G13/Psiquiatria!$F13 -> #DIV/0!
B14: 11 | C14: Psicopatologia | D14: Teoria | H14: =Psiquiatria!$G14/Psiquiatria!$F14 -> #DIV/0!
B15: 12 | C15: Psiquiatria Social e Reforma Psiquiátrica | D15: Teoria | H15: =Psiquiatria!$G15/Psiquiatria!$F15 -> #DIV/0!
... B20: 17 | C20: Psiquiatria Infantil | D20: Revisão | H20: =Psiquiatria!$G20/Psiquiatria!$F20 -> #DIV/0!
B21: Total | E21: =COUNTA(E4:E20) -> 0 | F21: =SUM(F4:F20) -> 0 | G21: =SUM(G4:G20) -> 0 | H21: =Psiquiatria!$G21/Psiquiatria!$F21 -> #DIV/0!

Sheet Neurologia
A1: Sim
C2: Sim | E2: PREENCHER | F2: PREENCHER | G2: PREENCHER | H2: NAO PREENCHER!
B3: Tarefa | C3: Assunto | D3: Tipo de Tarefa | E3: Realizada? | F3: Questões Feitas | G3: Acertos | H3: % Acertos
B4: 1 | C4: Anatomia, Fisiologia e Semiologia Neurológica | D4: Teoria | E4: Sim | F4: 100 | G4: 70 | H4: =Neurologia!$G4/Neurologia!$F4 -> 0.7
B5: 2 | C5: Coma e Alterações da Consciência | D5: Teoria I | H5: =Neurologia!$G5/Neurologia!$F5 -> #DIV/0!
B6: 3 | C6: Coma e Alterações da Consciência | D6: Teoria II | H6: =Neurologia!$G6/Neurologia!$F6 -> #DIV/0!
B7: 4 | C7: Coma e Alterações da Consciência | D7: Revisão | H7: =Neurologia!$G7/Neurologia!$F7 -> #DIV/0!
B8: 5 | C8: Traumatismo Cranioencefálico | D8: Teoria I | E8: Sim | F8: 25 | G8: 19 | H8: =Neurologia!$G8/Neurologia!$F8 -> 0.76
B9: 6 | C9: Traumatismo Cranioencefálico | D9: Teoria II | E9: Sim | F9: 20 | G9: 15 | H9: =Neurologia!$G9/Neurologia!$F9 -> 0.75
B10: 7 | C10: Traumatismo Cranioencefálico | D10: Revisão | H10: =Neurologia!$G10/Neurologia!$F10 -> #DIV/0!
B11: 8 | C11: Doenças Neuromusculares | D11: Teoria I | H11: =Neurologia!$G11/Neurologia!$F11 -> #DIV/0!
B12: 9 | C12: Doenças Neuromusculares | D12: Teoria II | H12: =Neurologia!$G12/Neurologia!$F12 -> #DIV/0!
B13: 10 | C13: Doenças Neuromusculares | D13: Revisão | H13: =Neurologia!$G13/Neurologia!$F13 -> #DIV/0!
B14: 11 | C14: Acidentes Vasculares Cerebrais | D14: Teoria | E14: Sim | F14: 100 | G14: 75 | H14: =Neurologia!$G14/Neurologia!$F14 -> 0.75
B15: 12 | C15: Acidentes Vasculares Cerebrais | D15: Revisão | H15: =Neurologia!$G15/Neurologia!$F15 -> #DIV/0!
B16: 13 | C16: Cefaleias | D16: Teoria I | H16: =Neurologia!$G16/Neurologia!$F16 -> #DIV/0!
B17: 14 | C17: Cefaleias | D17: Teoria II | H17: =Neurologia!$G17/Neurologia!$F17 -> #DIV/0!
B18: 15 | C18: Cefaleias | D18: Teoria III | H18: =Neurologia!$G18/Neurologia!$F18 -> #DIV/0!
B19: 16 | C19: Cefaleias | D19: Revisão | H19: =Neurologia!$G19/Neurologia!$F19 -> #DIV/0!
B20: 17 | C20: Demências | D20: Teoria | E20: Sim | F20: 135 | G20: 120 | H20: =Neurologia!$G20/Neurologia!$F20 -> 0.88888889
B21: 18 | C21: Epilepsias | D21: Teoria | E21: Sim | F21: 148 | G21: 115 | H21: =Neurologia!$G21/Neurologia!$F21 -> 0.77702703
B22: 19 | C22: Distúrbios do Movimento | D22: Teoria | H22: =Neurologia!$G22/Neurologia!$F22 -> #DIV/0!
B23: 20 | C23: Distúrbios do Movimento Demências Epilepsias | D23: Revisão | H23: =Neurologia!$G23/Neurologia!$F23 -> #DIV/0!
B24: Total | E24: =COUNTA(E4:E23) -> 6 | F24: =SUM(F4:F23) -> 528 | G24: =SUM(G4:G23) -> 414 | H24: =Neurologia!$G24/Neurologia!$F24 -> 0.78409091

Sheet Nefrologia
A1: Sim
C2: Sim | E2: PREENCHER | F2: PREENCHER | G2: PREENCHER | H2: NAO PREENCHER!
B3: Tarefa | C3: Assunto | D3: Tipo de Tarefa | E3: Realizada? | F3: Questões Feitas | G3: Acertos | H3: % Acertos
B4: 1 | C4: Doenças Glomerulares | D4: Teoria I | H4: =Nefrologia!$G4/Nefrologia!$F4 -> #DIV/0!
B5: 2 | C5: Doenças Glomerulares | D5: Teoria II | H5: =Nefrologia!$G5/Nefrologia!$F5 -> #DIV/0!
B6: 3 | C6: Doenças Glomerulares | D6: Revisão | H6: =Nefrologia!$G6/Nefrologia!$F6 -> #DIV/0!
B7: 4 | C7: Infecção do Trato Urinário | D7: Teoria | H7: =Nefrologia!$G7/Nefrologia!$F7 -> #DIV/0!
B8: 5 | C8: Infecção do Trato Urinário | D8: Revisão | H8: =Nefrologia!$G8/Nefrologia!$F8 -> #DIV/0!
B9: 6 | C9: Lesão Renal Aguda | D9: Teoria I | H9: =Nefrologia!$G9/Nefrologia!$F9 -> #DIV/0!
B10: 7 | C10: Lesão Renal Aguda | D10: Teoria II | H10: =Nefrologia!$G10/Nefrologia!$F10 -> #DIV/0!
B11: 8 | C11: Lesão Renal Aguda | D11: Teoria III | H11: =Nefrologia!$G11/Nefrologia!$F11 -> #DIV/0!
B12: 9 | C12: Lesão Renal Aguda | D12: Revisão | H12: =Nefrologia!$G12/Nefrologia!$F12 -> #DIV/0!
B13: 10 | C13: Distúrbios Ácido-Base | D13: Teoria | H13: =Nefrologia!$G13/Nefrologia!$F13 -> #DIV/0!
B14: 11 | C14: Distúrbios Ácido-Base | D14: Revisão | H14: =Nefrologia!$G14/Nefrologia!$F14 -> #DIV/0!
B15: 12 | C15: Doenças Glomerulares Infecção do Trato Urinário Lesão Renal Aguda Distúrbios Ácido-Base | D15: Revisão por Questões | H15: =Nefrologia!$G15/Nefrologia!$F15 -> #DIV/0!
... B25: 22 | C25: Distúrbios do Potássio Nefrolitíase Disnatremias | D25: Revisão por Questões | H25: =Nefrologia!$G25/Nefrologia!$F25 -> #DIV/0!
B26: 23 | C26: Doença Renal Crônica I e II | D26: Teoria | E26: Sim | F26: 40 | G26: 32 | H26: =Nefrologia!$G26/Nefrologia!$F26 -> 0.8
B27: Total | E27: =COUNTA(E4:E26) -> 1 | F27: =SUM(F4:F26) -> 40 | G27: =SUM(G4:G26) -> 32 | H27: =Nefrologia!$G27/Nefrologia!$F27 -> 0.8

Sheet Hematologia
A1: Sim
C2: Sim | E2: PREENCHER | F2: PREENCHER | G2: PREENCHER | H2: NAO PREENCHER!
B3: Tarefa | C3: Assunto | D3: Tipo de Tarefa | E3: Realizada? | F3: Questões Feitas | G3: Acertos | H3: % Acertos
B4: 1 | C4: Introdução ao Estudo das Anemias | D4: Teoria | H4: =Hematologia!$G4/Hematologia!$F4 -> #DIV/0!
B5: 2 | C5: Anemias Hemolíticas | D5: Teoria I | H5: =Hematologia!$G5/Hematologia!$F5 -> #DIV/0!
B6: 3 | C6: Anemias Hemolíticas | D6: Teoria II | H6: =Hematologia!$G6/Hematologia!$F6 -> #DIV/0!
B7: 4 | C7: Anemias Hemolíticas | D7: Teoria III | H7: =Hematologia!$G7/Hematologia!$F7 -> #DIV/0!
B8: 5 | C8: Anemias Hemolíticas | D8: Revisão | H8: =Hematologia!$G8/Hematologia!$F8 -> #DIV/0!
B9: 6 | C9: Leucemias Agudas | D9: Teoria I | H9: =Hematologia!$G9/Hematologia!$F9 -> #DIV/0!
B10: 7 | C10: Leucemias Agudas | D10: Teoria II | H10: =Hematologia!$G10/Hematologia!$F10 -> #DIV/0!
B11: 8 | C11: Leucemias Agudas | D11: Revisão | H11: =Hematologia!$G11/Hematologia!$F11 -> #DIV/0!
B12: 9 | C12: Hemostasia I | D12: Teoria I | E12: Sim | F12: 20 | G12: 18 | H12: =Hematologia!$G12/Hematologia!$F12 -> 0.9
B13: 10 | C13: Hemostasia I | D13: Teoria II | H13: =Hematologia!$G13/Hematologia!$F13 -> #DIV/0!
B14: 11 | C14: Hemostasia I | D14: Revisão | H14: =Hematologia!$G14/Hematologia!$F14 -> #DIV/0!
B15: 12 | C15: Hemostasia II | D15: Teoria I | H15: =Hematologia!$G15/Hematologia!$F15 -> #DIV/0!
B16: 13 | C16: Hemostasia II | D16: Teoria II | H16: =Hematologia!$G16/Hematologia!$F16 -> #DIV/0!
B17: 14 | C17: Hemostasia II | D17: Revisão | H17: =Hematologia!$G17/Hematologia!$F17 -> #DIV/0!
B18: 15 | C18: Anemias Microcíticas | D18: Teoria I | H18: =Hematologia!$G18/Hematologia!$F18 -> #DIV/0!
B19: 16 | C19: Anemias Microcíticas | D19: Teoria II | H19: =Hematologia!$G19/Hematologia!$F19 -> #DIV/0!
B20: 17 | C20: Anemias Microcíticas | D20: Revisão | H20: =Hematologia!$G20/Hematologia!$F20 -> #DIV/0!
B21: 18 | C21: Anemias Macrocíticas Leucemias Crônicas, Linfomas, Mielodisplasias e Mieloproliferações | D21: Teoria | H21: =Hematologia!$G21/Hematologia!$F21 -> #DIV/0!
B22: Total | E22: =COUNTA(E4:E21) -> 1 | F22: =SUM(F4:F21) -> 20 | G22: =SUM(G4:G21) -> 18 | H22: =Hematologia!$G22/Hematologia!$F22 -> 0.9

Sheet Pneumo
A1: Sim
C2: Sim | E2: PREENCHER | F2: PREENCHER | G2: PREENCHER | H2: NAO PREENCHER!
B3: Tarefa | C3: Assunto | D3: Tipo de Tarefa | E3: Realizada? | F3: Questões Feitas | G3: Acertos | H3: % Acertos
B4: 1 | C4: Introdução a Pneumologia | D4: Teoria | H4: =Pneumo!$G4/Pneumo!$F4 -> #DIV/0!
B5: 2 | C5: Pneumologia Intensiva | D5: Teoria I | H5: =Pneumo!$G5/Pneumo!$F5 -> #DIV/0!
B6: 3 | C6: Pneumologia Intensiva | D6: Teoria II | H6: =Pneumo!$G6/Pneumo!$F6 -> #DIV/0!
B7: 4 | C7: Pneumologia Intensiva | D7: Revisão I | H7: =Pneumo!$G7/Pneumo!$F7 -> #DIV/0!
B8: 5 | C8: Pneumologia Intensiva | D8: Teoria III | H8: =Pneumo!$G8/Pneumo!$F8 -> #DIV/0!
B9: 6 | C9: Pneumologia Intensiva | D9: Teoria IV | H9: =Pneumo!$G9/Pneumo!$F9 -> #DIV/0!
B10: 7 | C10: Pneumologia Intensiva | D10: Teoria V | H10: =Pneumo!$G10/Pneumo!$F10 -> #DIV/0!
B11: 8 | C11: Pneumologia Intensiva | D11: Revisão II | H11: =Pneumo!$G11/Pneumo!$F11 -> #DIV/0!
B12: 9 | C12: Neoplasias Pulmonares | D12: Teoria | H12: =Pneumo!$G12/Pneumo!$F12 -> #DIV/0!
B13: 10 | C13: Tromboembolismo Pulmonar | D13: Teoria | H13: =Pneumo!$G13/Pneumo!$F13 -> #DIV/0!
B14: 11 | C14: Doença Pulmonar Obstrutiva Crônica | D14: Teoria I | H14: =Pneumo!$G14/Pneumo!$F14 -> #DIV/0!
B15: 12 | C15: Doença Pulmonar Obstrutiva Crônica | D15: Teoria II | H15: =Pneumo!$G15/Pneumo!$F15 -> #DIV/0!
... B17: 14 | C17: Doença Pulmonar Obstrutiva Crônica | D17: Revisão | H17: =Pneumo!$G17/Pneumo!$F17 -> #DIV/0!
B18: 15 | C18: Asma | D18: Teoria I | E18: Sim | F18: 17 | G18: 12 | H18: =Pneumo!$G18/Pneumo!$F18 -> 0.70588235
B19: 16 | C19: Asma | D19: Teoria II | E19: Sim | F19: 27 | G19: 21 | H19: =Pneumo!$G19/Pneumo!$F19 -> 0.77777778
B20: 17 | C20: Asma | D20: Revisão | H20: =Pneumo!$G20/Pneumo!$F20 -> #DIV/0!
B21: 18 | C21: Derrame Pleural | D21: Teoria I | H21: =Pneumo!$G21/Pneumo!$F21 -> #DIV/0!
B22: 19 | C22: Derrame Pleural | D22: Teoria II | H22: =Pneumo!$G22/Pneumo!$F22 -> #DIV/0!
B23: 20 | C23: Derrame Pleural | D23: Revisão | H23: =Pneumo!$G23/Pneumo!$F23 -> #DIV/0!
B24: Total | E24: =COUNTA(E4:E23) -> 2 | F24: =SUM(F4:F23) -> 44 | G24: =SUM(G4:G23) -> 33 | H24: =Pneumo!$G24/Pneumo!$F24 -> 0.75

Sheet Dermato
A1: Sim
C2: Sim | E2: PREENCHER | F2: PREENCHER | G2: PREENCHER | H2: NAO PREENCHER!
B3: Tarefa | C3: Assunto | D3: Tipo de Tarefa | E3: Realizada? | F3: Questões Feitas | G3: Acertos | H3: % Acertos
B4: 1 | C4: Oncologia Cutânea (Câncer de Pele) | D4: Teoria I | H4: =Dermato!$G4/Dermato!$F4 -> #DIV/0!
B5: 2 | C5: Oncologia Cutânea (Câncer de Pele) | D5: Teoria II | H5: =Dermato!$G5/Dermato!$F5 -> #DIV/0!
B6: 3 | C6: Oncologia Cutânea (Câncer de Pele) | D6: Revisão | H6: =Dermato!$G6/Dermato!$F6 -> #DIV/0!
B7: 4 | C7: Hanseníase | D7: Teoria I | H7: =Dermato!$G7/Dermato!$F7 -> #DIV/0!
B8: 5 | C8: Hanseníase | D8: Teoria II | H8: =Dermato!$G8/Dermato!$F8 -> #DIV/0!
B9: 6 | C9: Hanseníase | D9: Revisão | H9: =Dermato!$G9/Dermato!$F9 -> #DIV/0!
B10: 7 | C10: Síndromes Verrucosas | D10: Teoria | H10: =Dermato!$G10/Dermato!$F10 -> #DIV/0!
B11: 8 | C11: Síndromes Verrucosas | D11: Revisão | H11: =Dermato!$G11/Dermato!$F11 -> #DIV/0!
B12: 9 | C12: Dermatoses Infecciosas Dermatoses Eczematosas | D12: Teoria | H12: =Dermato!$G12/Dermato!$F12 -> #DIV/0!
B13: Total | E13: =COUNTA(E4:E12) -> 0 | F13: =SUM(F4:F12) -> 0 | G13: =SUM(G4:G12) -> 0 | H13: =Dermato!$G13/Dermato!$F13 -> #DIV/0!

Sheet Reumato
A1: Sim
C2: Sim | E2: PREENCHER | F2: PREENCHER | G2: PREENCHER | H2: NAO PREENCHER!
B3: Tarefa | C3: Assunto | D3: Tipo de Tarefa | E3: Realizada? | F3: Questões Feitas | G3: Acertos | H3: % Acertos
B4: 1 | C4: Doenças Inflamatória do Tecido Conjuntivo I | D4: Teoria I | H4: =Reumato!$G4/Reumato!$F4 -> #DIV/0!
B5: 2 | C5: Doenças Inflamatória do Tecido Conjuntivo I | D5: Teoria II | H5: =Reumato!$G5/Reumato!$F5 -> #DIV/0!
B6: 3 | C6: Doenças Inflamatória do Tecido Conjuntivo I | D6: Teoria III | H6: =Reumato!$G6/Reumato!$F6 -> #DIV/0!
B7: 4 | C7: Doenças Inflamatória do Tecido Conjuntivo I | D7: Revisão | H7: =Reumato!$G7/Reumato!$F7 -> #DIV/0!
B8: 5 | C8: Doenças Inflamatória do Tecido Conjuntivo II | D8: Teoria I | H8: =Reumato!$G8/Reumato!$F8 -> #DIV/0!
B9: 6 | C9: Doenças Inflamatória do Tecido Conjuntivo II | D9: Teoria II | H9: =Reumato!$G9/Reumato!$F9 -> #DIV/0!
B10: 7 | C10: Doenças Inflamatória do Tecido Conjuntivo II | D10: Revisão I | H10: =Reumato!$G10/Reumato!$F10 -> #DIV/0!
B11: 8 | C11: Doenças Inflamatória do Tecido Conjuntivo II | D11: Teoria III | H11: =Reumato!$G11/Reumato!$F11 -> #DIV/0!
B12: 9 | C12: Doenças Inflamatória do Tecido Conjuntivo II | D12: Teoria IV | H12: =Reumato!$G12/Reumato!$F12 -> #DIV/0!
B13: 10 | C13: Doenças Inflamatória do Tecido Conjuntivo II | D13: Revisão | H13: =Reumato!$G13/Reumato!$F13 -> #DIV/0!
B14: 11 | C14: Artrite Reumatoide | D14: Teoria | H14: =Reumato!$G14/Reumato!$F14 -> #DIV/0!
B15: 12 | C15: Vasculites | D15: Teoria I | H15: =Reumato!$G15/Reumato!$F15 -> #DIV/0!
... B20: 17 | C20: Síndromes Dolorosas Crônicas | D20: Teoria | H20: =Reumato!$G20/Reumato!$F20 -> #DIV/0!
B21: Total | E21: =COUNTA(E4:E20) -> 0 | F21: =SUM(F4:F20) -> 0 | G21: =SUM(G4:G20) -> 0 | H21: =Reumato!$G21/Reumato!$F21 -> #DIV/0!

Sheet Hepato
A1: Sim
C2: Sim | E2: PREENCHER | F2: PREENCHER | G2: PREENCHER | H2: NAO PREENCHER!
B3: Tarefa | C3: Assunto | D3: Tipo de Tarefa | E3: Realizada? | F3: Questões Feitas | G3: Acertos | H3: % Acertos
B4: 1 | C4: Introdução à Hepatologia e Icterícia Não Obstrutiva | D4: Teoria | H4: =Hepato!$G4/Hepato!$F4 -> #DIV/0!
B5: 2 | C5: Hepatites Virais | D5: Teoria I | H5: =Hepato!$G5/Hepato!$F5 -> #DIV/0!
B6: 3 | C6: Hepatites Virais | D6: Teoria II | H6: =Hepato!$G6/Hepato!$F6 -> #DIV/0!
B7: 4 | C7: Hepatites Virais | D7: Teoria III | H7: =Hepato!$G7/Hepato!$F7 -> #DIV/0!
B8: 5 | C8: Hepatites Virais | D8: Revisão I | H8: =Hepato!$G8/Hepato!$F8 -> #DIV/0!
B9: 6 | C9: Hepatites Virais | D9: Teoria IV | H9: =Hepato!$G9/Hepato!$F9 -> #DIV/0!
B10: 7 | C10: Hepatites Virais | D10: Teoria V | H10: =Hepato!$G10/Hepato!$F10 -> #DIV/0!
B11: 8 | C11: Hepatites Virais | D11: Revisão II | H11: =Hepato!$G11/Hepato!$F11 -> #DIV/0!
B12: 9 | C12: Complicações da Cirrose Hepática | D12: Teoria I | H12: =Hepato!$G12/Hepato!$F12 -> #DIV/0!
B13: 10 | C13: Complicações da Cirrose Hepática | D13: Teoria II | H13: =Hepato!$G13/Hepato!$F13 -> #DIV/0!
B14: 11 | C14: Complicações da Cirrose Hepática | D14: Revisão I | H14: =Hepato!$G14/Hepato!$F14 -> #DIV/0!
B15: 12 | C15: Complicações da Cirrose Hepática | D15: Teoria III | H15: =Hepato!$G15/Hepato!$F15 -> #DIV/0!
... B21: 18 | C21: Tumores Hepáticos | D21: Revisão | H21: =Hepato!$G21/Hepato!$F21 -> #DIV/0!
B22: Total | E22: =COUNTA(E4:E21) -> 0 | F22: =SUM(F4:F21) -> 0 | G22: =SUM(G4:G21) -> 0 | H22: =Hepato!$G22/Hepato!$F22 -> #DIV/0!

Sheet Otorrino
A1: Sim
C2: Sim | E2: PREENCHER | F2: PREENCHER | G2: PREENCHER | H2: NAO PREENCHER!
B3: Tarefa | C3: Assunto | D3: Tipo de Tarefa | E3: Realizada? | F3: Questões Feitas | G3: Acertos | H3: % Acertos
B4: 1 | C4: Neoplasias beningas e malignas de cabeça e pescoço, doenças congênitas cervicofaciais e traqueostomia | D4: Teoria I | H4: =Otorrino!$G4/Otorrino!$F4 -> #DIV/0!
B5: 2 | C5: Neoplasias beningas e malignas de cabeça e pescoço, doenças congênitas cervicofaciais e traqueostomia | D5: Teoria II | H5: =Otorrino!$G5/Otorrino!$F5 -> #DIV/0!
B6: 3 | C6: Neoplasias beningas e malignas de cabeça e pescoço, doenças congênitas cervicofaciais e traqueostomia | D6: Revisão | H6: =Otorrino!$G6/Otorrino!$F6 -> #DIV/0!
B7: 4 | C7: Infecções das Vias Aéreas Superiores Pt. 1 | D7: Teoria I | H7: =Otorrino!$G7/Otorrino!$F7 -> #DIV/0!
B8: 5 | C8: Infecções das Vias Aéreas Superiores Pt. 1 | D8: Teoria II | H8: =Otorrino!$G8/Otorrino!$F8 -> #DIV/0!
B9: 6 | C9: Infecções das Vias Aéreas Superiores Pt. 1 | D9: Revisão | H9: =Otorrino!$G9/Otorrino!$F9 -> #DIV/0!
B10: 7 | C10: Infecções das Vias Aéreas Superiores Pt. 2 | D10: Teoria I | H10: =Otorrino!$G10/Otorrino!$F10 -> #DIV/0!
B11: 8 | C11: Infecções das Vias Aéreas Superiores Pt. 2 | D11: Teoria II | H11: =Otorrino!$G11/Otorrino!$F11 -> #DIV/0!
B12: 9 | C12: Infecções das Vias Aéreas Superiores Pt. 2 | D12: Revisão | H12: =Otorrino!$G12/Otorrino!$F12 -> #DIV/0!
B13: 10 | C13: Manejo dos Nódulos de Tireoide, Câncer de Tireoide e Tireoidectomia | D13: Teoria | H13: =Otorrino!$G13/Otorrino!$F13 -> #DIV/0!
B14: 11 | C14: Infecções das Vias Aéreas Superiores Pt. 3 | D14: Teoria | H14: =Otorrino!$G14/Otorrino!$F14 -> #DIV/0!
B15: Total | E15: =COUNTA(E4:E14) -> 0 | F15: =SUM(F4:F14) -> 0 | G15: =SUM(G4:G14) -> 0 | H15: =Otorrino!$G15/Otorrino!$F15 -> #DIV/0!

Sheet Ortopedia
A1: Sim
C2: Sim | E2: PREENCHER | F2: PREENCHER | G2: PREENCHER | H2: NAO PREENCHER!
B3: Tarefa | C3: Assunto | D3: Tipo de Tarefa | E3: Realizada? | F3: Questões Feitas | G3: Acertos | H3: % Acertos
B4: 1 | C4: Quadril Pediátrico | D4: Teoria I | H4: =Ortopedia!$G4/Ortopedia!$F4 -> #DIV/0!
B5: 2 | C5: Quadril Pediátrico | D5: Teoria II | H5: =Ortopedia!$G5/Ortopedia!$F5 -> #DIV/0!
B6: 3 | C6: Quadril Pediátrico | D6: Revisão | H6: =Ortopedia!$G6/Ortopedia!$F6 -> #DIV/0!
B7: 4 | C7: Politrauma Ortopédico | D7: Teoria I | H7: =Ortopedia!$G7/Ortopedia!$F7 -> #DIV/0!
B8: 5 | C8: Politrauma Ortopédico | D8: Teoria II | H8: =Ortopedia!$G8/Ortopedia!$F8 -> #DIV/0!
B9: 6 | C9: Politrauma Ortopédico | D9: Teoria III | H9: =Ortopedia!$G9/Ortopedia!$F9 -> #DIV/0!
B10: 7 | C10: Politrauma Ortopédico | D10: Revisão | H10: =Ortopedia!$G10/Ortopedia!$F10 -> #DIV/0!
B11: 8 | C11: Maus Tratos | D11: Teoria | H11: =Ortopedia!$G11/Ortopedia!$F11 -> #DIV/0!
B12: 9 | C12: Maus Tratos | D12: Revisão | H12: =Ortopedia!$G12/Ortopedia!$F12 -> #DIV/0!
B13: 10 | C13: Conceitos Básicos do Trauma Ortopédico | D13: Teoria | H13: =Ortopedia!$G13/Ortopedia!$F13 -> #DIV/0!
B14: 11 | C14: Miscelânea Ortopédica | D14: Teoria | H14: =Ortopedia!$G14/Ortopedia!$F14 -> #DIV/0!
B15: 12 | C15: Complicações do Trauma Ortopédico | D15: Teoria | H15: =Ortopedia!$G15/Ortopedia!$F15 -> #DIV/0!
... B17: 14 | C17: Doenças da Coluna Vertebral | D17: Teoria | H17: =Ortopedia!$G17/Ortopedia!$F17 -> #DIV/0!
B18: Total | E18: =COUNTA(E4:E17) -> 0 | F18: =SUM(F4:F17) -> 0 | G18: =SUM(G4:G17) -> 0 | H18: =Ortopedia!$G18/Ortopedia!$F18 -> #DIV/0!

Sheet Oftalmo
A1: Sim
C2: Sim | E2: PREENCHER | F2: PREENCHER | G2: PREENCHER | H2: NAO PREENCHER!
B3: Tarefa | C3: Assunto | D3: Tipo de Tarefa | E3: Realizada? | F3: Questões Feitas | G3: Acertos | H3: % Acertos
B4: 1 | C4: Síndrome do Olho Vermelho | D4: Teoria I | H4: =Oftalmo!$G4/Oftalmo!$F4 -> #DIV/0!
B5: 2 | C5: Síndrome do Olho Vermelho | D5: Teoria II | H5: =Oftalmo!$G5/Oftalmo!$F5 -> #DIV/0!
B6: 3 | C6: Síndrome do Olho Vermelho | D6: Revisão | H6: =Oftalmo!$G6/Oftalmo!$F6 -> #DIV/0!
B7: 4 | C7: Doenças do Polo Posterior | D7: Teoria I | H7: =Oftalmo!$G7/Oftalmo!$F7 -> #DIV/0!
B8: 5 | C8: Doenças do Polo Posterior | D8: Teoria II | H8: =Oftalmo!$G8/Oftalmo!$F8 -> #DIV/0!
B9: 6 | C9: Doenças do Polo Posterior | D9: Revisão | H9: =Oftalmo!$G9/Oftalmo!$F9 -> #DIV/0!
B10: 7 | C10: Glaucoma | D10: Teoria | H10: =Oftalmo!$G10/Oftalmo!$F10 -> #DIV/0!
B11: Total | E11: =COUNTA(E4:E10) -> 0 | F11: =SUM(F4:F10) -> 0 | G11: =SUM(G4:G10) -> 0 | H11: =Oftalmo!$G11/Oftalmo!$F11 -> #DIV/0!

Sheet Simulado Final 1
B3: Tarefa 1 | G3: Tarefa 2 | L3: Tarefa 3 | Q3: Tarefa 4 | V3: Tarefa 5 | AA3: Tarefa 6 | AF3: Tarefa 7
B4: Disciplina | C4: Questões Feitas | D4: Acertos | E4: % Acertos | G4: Disciplina | H4: Questões Feitas | I4: Acertos | J4: % Acertos | L4: Disciplina | M4: Questões Feitas | N4: Acertos | O4: % Acertos | Q4: Disciplina | R4: Questões Feitas | S4: Acertos | T4: % Acertos | V4: Disciplina | W4: Questões Feitas | X4: Acertos | Y4: % Acertos | AA4: Disciplina | AB4: Questões Feitas | AC4: Acertos | AD4: % Acertos | AF4: Disciplina | AG4: Questões Feitas | AH4: Acertos | AI4: % Acertos
